<?xml version="1.0" encoding="utf-8"?>
<!-- This URDF was automatically created by SolidWorks to URDF Exporter! Originally created by Stephen Brawner (brawner@gmail.com) 
     Commit Version: 1.6.0-1-g15f4949  Build Version: 1.6.7594.29634
     For more information, please see http://wiki.ros.org/sw_urdf_exporter -->
<robot
  name="myhexapod_description">
  <link
    name="base_link">
    <inertial>
      <origin
        xyz="-0.000641062587610375 -0.0270610806424069 0.0130383041801076"
        rpy="0 0 0" />
      <mass
        value="0.154954966549661" />
      <inertia
        ixx="0.000288482455992446"
        ixy="1.34615337721131E-07"
        ixz="-2.19476667889284E-09"
        iyy="0.000102286533156623"
        iyz="-1.87029729705504E-06"
        izz="0.00037996489569889" />
    </inertial>
    <visual>
      <origin
        xyz="0 0 0"
        rpy="0 0 0" />
      <geometry>
        <mesh
          filename="package://myhexapod_description/meshes/base_link.STL" />
      </geometry>
      <material
        name="">
        <color
          rgba="0.141176470588235 0.00784313725490196 1 1" />
      </material>
    </visual>
    <collision>
      <origin
        xyz="0 0 0"
        rpy="0 0 0" />
      <geometry>
        <mesh
          filename="package://myhexapod_description/meshes/base_link.STL" />
      </geometry>
    </collision>
  </link>
  <link
    name="link1_l1">
    <inertial>
      <origin
        xyz="-0.00806224601063825 -0.00672597588241393 -0.0222013878562005"
        rpy="0 0 0" />
      <mass
        value="0.0173848381350191" />
      <inertia
        ixx="1.80098683466882E-06"
        ixy="2.71142412938623E-08"
        ixz="1.76406239213805E-08"
        iyy="1.03469767138463E-06"
        iyz="9.20330157264301E-09"
        izz="1.46962126426456E-06" />
    </inertial>
    <visual>
      <origin
        xyz="0 0 0"
        rpy="0 0 0" />
      <geometry>
        <mesh
          filename="package://myhexapod_description/meshes/link1_l1.STL" />
      </geometry>
      <material
        name="">
        <color
          rgba="0.792156862745098 0.819607843137255 0.933333333333333 1" />
      </material>
    </visual>
    <collision>
      <origin
        xyz="0 0 0"
        rpy="0 0 0" />
      <geometry>
        <mesh
          filename="package://myhexapod_description/meshes/link1_l1.STL" />
      </geometry>
    </collision>
  </link>
  <joint
    name="joint1_l1"
    type="continuous">
    <origin
      xyz="-0.0471900957377952 -0.0846909980170476 0.0333"
      rpy="0 0 0" />
    <parent
      link="base_link" />
    <child
      link="link1_l1" />
    <axis
      xyz="0 0 -1" />
  </joint>
  <link
    name="link2_l1">
    <inertial>
      <origin
        xyz="-0.0207284792608098 -0.00457298257654315 -6.32878782574897E-05"
        rpy="0 0 0" />
      <mass
        value="0.00241602750324229" />
      <inertia
        ixx="7.84746554197057E-08"
        ixy="-2.18303559732558E-08"
        ixz="6.40685205735395E-08"
        iyy="6.95959480864615E-07"
        iyz="2.26223346089884E-09"
        izz="6.22650508720032E-07" />
    </inertial>
    <visual>
      <origin
        xyz="0 0 0"
        rpy="0 0 0" />
      <geometry>
        <mesh
          filename="package://myhexapod_description/meshes/link2_l1.STL" />
      </geometry>
      <material
        name="">
        <color
          rgba="1 1 1 0.9" />
      </material>
    </visual>
    <collision>
      <origin
        xyz="0 0 0"
        rpy="0 0 0" />
      <geometry>
        <mesh
          filename="package://myhexapod_description/meshes/link2_l1.STL" />
      </geometry>
    </collision>
  </link>
  <joint
    name="joint2_l1"
    type="continuous">
    <origin
      xyz="-0.0173549775040496 -0.0185853143585623 -0.0243000000000001"
      rpy="0 0 0" />
    <parent
      link="link1_l1" />
    <child
      link="link2_l1" />
    <axis
      xyz="0.0352876033106527 -0.999377198585494 0" />
  </joint>
  <link
    name="link3_l1">
    <inertial>
      <origin
        xyz="-0.0017555342898588 0.0100933773966093 -0.0104738727826697"
        rpy="0 0 0" />
      <mass
        value="0.00980520879192993" />
      <inertia
        ixx="2.67590341746477E-06"
        ixy="3.39637519317928E-09"
        ixz="1.18964160199247E-07"
        iyy="2.55009275257376E-06"
        iyz="4.77822904017731E-08"
        izz="4.6298144105811E-07" />
    </inertial>
    <visual>
      <origin
        xyz="0 0 0"
        rpy="0 0 0" />
      <geometry>
        <mesh
          filename="package://myhexapod_description/meshes/link3_l1.STL" />
      </geometry>
      <material
        name="">
        <color
          rgba="1 0.0313725490196078 0.0627450980392157 1" />
      </material>
    </visual>
    <collision>
      <origin
        xyz="0 0 0"
        rpy="0 0 0" />
      <geometry>
        <mesh
          filename="package://myhexapod_description/meshes/link3_l1.STL" />
      </geometry>
    </collision>
  </link>
  <joint
    name="joint3_l1"
    type="continuous">
    <origin
      xyz="-0.0411588142263402 -0.00145330102709124 0.0047797512185247"
      rpy="0 0 0" />
    <parent
      link="link2_l1" />
    <child
      link="link3_l1" />
    <axis
      xyz="-0.0352876033106511 0.999377198585494 0" />
  </joint>
  <link
    name="link1_l2">
    <inertial>
      <origin
        xyz="-0.00710042179359962 0.00727262552574385 -0.0222013878562004"
        rpy="0 0 0" />
      <mass
        value="0.017384838135019" />
      <inertia
        ixx="1.77701480207914E-06"
        ixy="-1.36125062093018E-07"
        ixz="3.18145809512914E-08"
        iyy="1.05866970397431E-06"
        iyz="7.40362709343975E-08"
        izz="1.46962126426456E-06" />
    </inertial>
    <visual>
      <origin
        xyz="0 0 0"
        rpy="0 0 0" />
      <geometry>
        <mesh
          filename="package://myhexapod_description/meshes/link1_l2.STL" />
      </geometry>
      <material
        name="">
        <color
          rgba="0.792156862745098 0.819607843137255 0.933333333333333 1" />
      </material>
    </visual>
    <collision>
      <origin
        xyz="0 0 0"
        rpy="0 0 0" />
      <geometry>
        <mesh
          filename="package://myhexapod_description/meshes/link1_l2.STL" />
      </geometry>
    </collision>
  </link>
  <joint
    name="joint1_l2"
    type="continuous">
    <origin
      xyz="-0.0547460900589758 -0.00891354966241674 0.0333000000000001"
      rpy="0 0 0" />
    <parent
      link="base_link" />
    <child
      link="link1_l2" />
    <axis
      xyz="0 0 -1" />
  </joint>
  <link
    name="link2_l2">
    <inertial>
      <origin
        xyz="-0.0221179474264141 -0.00489499778216674 0.000354952301372807"
        rpy="0 0 0" />
      <mass
        value="0.00241602750324229" />
      <inertia
        ixx="1.00495695982353E-07"
        ixy="1.09214191161804E-07"
        ixz="7.3744760369015E-08"
        iyy="6.76725190743576E-07"
        iyz="-1.3508062558812E-08"
        izz="6.19863758278428E-07" />
    </inertial>
    <visual>
      <origin
        xyz="0 0 0"
        rpy="0 0 0" />
      <geometry>
        <mesh
          filename="package://myhexapod_description/meshes/link2_l2.STL" />
      </geometry>
      <material
        name="">
        <color
          rgba="1 1 1 0.9" />
      </material>
    </visual>
    <collision>
      <origin
        xyz="0 0 0"
        rpy="0 0 0" />
      <geometry>
        <mesh
          filename="package://myhexapod_description/meshes/link2_l2.STL" />
      </geometry>
    </collision>
  </link>
  <joint
    name="joint2_l2"
    type="continuous">
    <origin
      xyz="-0.0177054207597022 0.00324315829430281 -0.0243"
      rpy="0 0 0" />
    <parent
      link="link1_l2" />
    <child
      link="link2_l2" />
    <axis
      xyz="-0.180175460794602 -0.983634486650124 0" />
  </joint>
  <link
    name="link3_l2">
    <inertial>
      <origin
        xyz="-0.000312121590769401 0.00533120047156848 -0.0104904932407494"
        rpy="0 0 0" />
      <mass
        value="0.00980520879192992" />
      <inertia
        ixx="2.66809055091214E-06"
        ixy="-2.32210800768185E-08"
        ixz="1.53550230931468E-07"
        iyy="2.5545549293717E-06"
        iyz="1.61362010316771E-08"
        izz="4.66332130812788E-07" />
    </inertial>
    <visual>
      <origin
        xyz="0 0 0"
        rpy="0 0 0" />
      <geometry>
        <mesh
          filename="package://myhexapod_description/meshes/link3_l2.STL" />
      </geometry>
      <material
        name="">
        <color
          rgba="1 0.0313725490196078 0.0627450980392157 1" />
      </material>
    </visual>
    <collision>
      <origin
        xyz="0 0 0"
        rpy="0 0 0" />
      <geometry>
        <mesh
          filename="package://myhexapod_description/meshes/link3_l2.STL" />
      </geometry>
    </collision>
  </link>
  <joint
    name="joint3_l2"
    type="continuous">
    <origin
      xyz="-0.0404081437582719 0.00740168835102142 0.00560383990402152"
      rpy="0 0 0" />
    <parent
      link="link2_l2" />
    <child
      link="link3_l2" />
    <axis
      xyz="0.180175460794602 0.983634486650124 0" />
  </joint>
  <link
    name="link1_l3">
    <inertial>
      <origin
        xyz="-0.00559630373279337 0.159627292837933 -0.0222013878562003"
        rpy="0 0 0" />
      <mass
        value="0.017384838135019" />
      <inertia
        ixx="1.68583311520164E-06"
        ixy="-2.75165132808249E-07"
        ixz="4.70849584426385E-08"
        iyy="1.1498513908518E-06"
        iyz="6.53952877769699E-08"
        izz="1.46962126426456E-06" />
    </inertial>
    <visual>
      <origin
        xyz="0 0 0"
        rpy="0 0 0" />
      <geometry>
        <mesh
          filename="package://myhexapod_description/meshes/link1_l3.STL" />
      </geometry>
      <material
        name="">
        <color
          rgba="0.792156862745098 0.819607843137255 0.933333333333333 1" />
      </material>
    </visual>
    <collision>
      <origin
        xyz="0 0 0"
        rpy="0 0 0" />
      <geometry>
        <mesh
          filename="package://myhexapod_description/meshes/link1_l3.STL" />
      </geometry>
    </collision>
  </link>
  <joint
    name="joint1_l3"
    type="continuous">
    <origin
      xyz="-0.0471900957377952 -0.0846909980170476 0.0333"
      rpy="0 0 0" />
    <parent
      link="base_link" />
    <child
      link="link1_l3" />
    <axis
      xyz="0 0 -1" />
  </joint>
  <link
    name="link2_l3">
    <inertial>
      <origin
        xyz="-0.0188207467364196 0.00907835344817356 -0.000555639138620834"
        rpy="0 0 0" />
      <mass
        value="0.0024160275032423" />
      <inertia
        ixx="1.68972312493501E-07"
        ixy="2.22717643256588E-07"
        ixz="4.71610141228835E-08"
        iyy="6.02741864720202E-07"
        iyz="-1.99022850063415E-08"
        izz="6.25370467790657E-07" />
    </inertial>
    <visual>
      <origin
        xyz="0 0 0"
        rpy="0 0 0" />
      <geometry>
        <mesh
          filename="package://myhexapod_description/meshes/link2_l3.STL" />
      </geometry>
      <material
        name="">
        <color
          rgba="1 1 1 0.9" />
      </material>
    </visual>
    <collision>
      <origin
        xyz="0 0 0"
        rpy="0 0 0" />
      <geometry>
        <mesh
          filename="package://myhexapod_description/meshes/link2_l3.STL" />
      </geometry>
    </collision>
  </link>
  <joint
    name="joint2_l3"
    type="continuous">
    <origin
      xyz="-0.0208009289168688 0.148560267673523 -0.0243"
      rpy="0 0 0" />
    <parent
      link="link1_l3" />
    <child
      link="link2_l3" />
    <axis
      xyz="-0.388803857549591 -0.92132055244337 0" />
  </joint>
  <link
    name="link3_l3">
    <inertial>
      <origin
        xyz="0.00266988679925712 0.199705379975006 -0.0110761933807784"
        rpy="0 0 0" />
      <mass
        value="0.00980520879192993" />
      <inertia
        ixx="2.64401172165923E-06"
        ixy="-3.35724891912431E-08"
        ixz="-2.07439429106529E-07"
        iyy="2.56160473008994E-06"
        iyz="1.34363357699381E-07"
        izz="4.83361159347462E-07" />
    </inertial>
    <visual>
      <origin
        xyz="0 0 0"
        rpy="0 0 0" />
      <geometry>
        <mesh
          filename="package://myhexapod_description/meshes/link3_l3.STL" />
      </geometry>
      <material
        name="">
        <color
          rgba="1 0.0313725490196078 0.0627450980392157 1" />
      </material>
    </visual>
    <collision>
      <origin
        xyz="0 0 0"
        rpy="0 0 0" />
      <geometry>
        <mesh
          filename="package://myhexapod_description/meshes/link3_l3.STL" />
      </geometry>
    </collision>
  </link>
  <joint
    name="joint3_l3"
    type="continuous">
    <origin
      xyz="-0.037712862813521 -0.168598883059176 0.00477975121852461"
      rpy="0 0 0" />
    <parent
      link="link2_l3" />
    <child
      link="link3_l3" />
    <axis
      xyz="0.388803857549592 0.92132055244337 0" />
  </joint>
  <link
    name="link1_l4">
    <inertial>
      <origin
        xyz="0.00858454154537591 0.00477409595308455 -0.0222013878562005"
        rpy="0 0 0" />
      <mass
        value="0.0173848381350191" />
      <inertia
        ixx="1.79938665850158E-06"
        ixy="-4.42585491569089E-08"
        ixz="-1.33885078663585E-08"
        iyy="1.03629784755187E-06"
        iyz="7.94649335374177E-08"
        izz="1.46962126426456E-06" />
    </inertial>
    <visual>
      <origin
        xyz="0 0 0"
        rpy="0 0 0" />
      <geometry>
        <mesh
          filename="package://myhexapod_description/meshes/link1_l4.STL" />
      </geometry>
      <material
        name="">
        <color
          rgba="0.792156862745098 0.819607843137255 0.933333333333333 1" />
      </material>
    </visual>
    <collision>
      <origin
        xyz="0 0 0"
        rpy="0 0 0" />
      <geometry>
        <mesh
          filename="package://myhexapod_description/meshes/link1_l4.STL" />
      </geometry>
    </collision>
  </link>
  <joint
    name="joint1_l4"
    type="continuous">
    <origin
      xyz="0.0471936701061024 0.0668638986922139 0.0333"
      rpy="0 0 0" />
    <parent
      link="base_link" />
    <child
      link="link1_l4" />
    <axis
      xyz="0 0 -1" />
  </joint>
  <link
    name="link2_l4">
    <inertial>
      <origin
        xyz="0.0207532049037457 -0.00269276074090919 -0.000352440731172715"
        rpy="0 0 0" />
      <mass
        value="0.0024160275032423" />
      <inertia
        ixx="7.81019403585742E-08"
        ixy="3.57786878004928E-08"
        ixz="-5.64423956478039E-08"
        iyy="6.94661023160162E-07"
        iyz="3.26437483022162E-09"
        izz="6.24321681485624E-07" />
    </inertial>
    <visual>
      <origin
        xyz="0 0 0"
        rpy="0 0 0" />
      <geometry>
        <mesh
          filename="package://myhexapod_description/meshes/link2_l4.STL" />
      </geometry>
      <material
        name="">
        <color
          rgba="1 1 1 0.9" />
      </material>
    </visual>
    <collision>
      <origin
        xyz="0 0 0"
        rpy="0 0 0" />
      <geometry>
        <mesh
          filename="package://myhexapod_description/meshes/link2_l4.STL" />
      </geometry>
    </collision>
  </link>
  <joint
    name="joint2_l4"
    type="continuous">
    <origin
      xyz="0.0174901594158788 -0.0093354403553265 -0.0243000000000001"
      rpy="0 0 0" />
    <parent
      link="link1_l4" />
    <child
      link="link2_l4" />
    <axis
      xyz="-0.0577390252809657 -0.998331710885517 0" />
  </joint>
  <link
    name="link3_l4">
    <inertial>
      <origin
        xyz="0.00241223215176936 0.0123790893395617 -0.0104302153534764"
        rpy="0 0 0" />
      <mass
        value="0.00980520879192993" />
      <inertia
        ixx="2.68057069459127E-06"
        ixy="-7.7323969964147E-09"
        ixz="-5.53105769727056E-08"
        iyy="2.55046755858813E-06"
        iyz="4.68385406449063E-08"
        izz="4.57939357917236E-07" />
    </inertial>
    <visual>
      <origin
        xyz="0 0 0"
        rpy="0 0 0" />
      <geometry>
        <mesh
          filename="package://myhexapod_description/meshes/link3_l4.STL" />
      </geometry>
      <material
        name="">
        <color
          rgba="1 0.0313725490196078 0.0627450980392157 1" />
      </material>
    </visual>
    <collision>
      <origin
        xyz="0 0 0"
        rpy="0 0 0" />
      <geometry>
        <mesh
          filename="package://myhexapod_description/meshes/link3_l4.STL" />
      </geometry>
    </collision>
  </link>
  <joint
    name="joint3_l4"
    type="continuous">
    <origin
      xyz="0.0411779045179998 -0.00238154517587446 0.00420886162596207"
      rpy="0 0 0" />
    <parent
      link="link2_l4" />
    <child
      link="link3_l4" />
    <axis
      xyz="-0.0577390252809635 -0.998331710885517 0" />
  </joint>
  <link
    name="link1_l5">
    <inertial>
      <origin
        xyz="0.00873927365415988 0.00519006764743294 -0.0222013878562002"
        rpy="0 0 0" />
      <mass
        value="0.017384838135019" />
      <inertia
        ixx="1.79700109923434E-06"
        ixy="-6.14289985686242E-08"
        ixz="-1.15918878895549E-08"
        iyy="1.0386834068191E-06"
        iyz="7.97468240129334E-08"
        izz="1.46962126426456E-06" />
    </inertial>
    <visual>
      <origin
        xyz="0 0 0"
        rpy="0 0 0" />
      <geometry>
        <mesh
          filename="package://myhexapod_description/meshes/link1_l5.STL" />
      </geometry>
      <material
        name="">
        <color
          rgba="0.792156862745098 0.819607843137255 0.933333333333333 1" />
      </material>
    </visual>
    <collision>
      <origin
        xyz="0 0 0"
        rpy="0 0 0" />
      <geometry>
        <mesh
          filename="package://myhexapod_description/meshes/link1_l5.STL" />
      </geometry>
    </collision>
  </link>
  <joint
    name="joint1_l5"
    type="continuous">
    <origin
      xyz="0.0547496644272887 -0.00891354966243538 0.0333"
      rpy="0 0 0" />
    <parent
      link="base_link" />
    <child
      link="link1_l5" />
    <axis
      xyz="0 0 -1" />
  </joint>
  <link
    name="link2_l5">
    <inertial>
      <origin
        xyz="0.0206900099595151 -0.00315127272238894 -0.000189656765370805"
        rpy="0 0 0" />
      <mass
        value="0.00241602750324229" />
      <inertia
        ixx="8.09394177036942E-08"
        ixy="4.95788185811713E-08"
        ixz="-6.0609072985197E-08"
        iyy="6.92738590865232E-07"
        iyz="4.87978356151068E-09"
        izz="6.23406636435432E-07" />
    </inertial>
    <visual>
      <origin
        xyz="0 0 0"
        rpy="0 0 0" />
      <geometry>
        <mesh
          filename="package://myhexapod_description/meshes/link2_l5.STL" />
      </geometry>
      <material
        name="">
        <color
          rgba="1 1 1 0.9" />
      </material>
    </visual>
    <collision>
      <origin
        xyz="0 0 0"
        rpy="0 0 0" />
      <geometry>
        <mesh
          filename="package://myhexapod_description/meshes/link2_l5.STL" />
      </geometry>
    </collision>
  </link>
  <joint
    name="joint2_l5"
    type="continuous">
    <origin
      xyz="0.0173545462599849 -0.00874026266286172 -0.0242999999999998"
      rpy="0 0 0" />
    <parent
      link="link1_l5" />
    <child
      link="link2_l5" />
    <axis
      xyz="-0.080252737926137 -0.996774547254974 0" />
  </joint>
  <link
    name="link3_l5">
    <inertial>
      <origin
        xyz="0.00241708833003226 0.0123529032428559 -0.00878674711215147"
        rpy="0 0 0" />
      <mass
        value="0.00980520879192993" />
      <inertia
        ixx="2.67852109163133E-06"
        ixy="-1.00001645453249E-08"
        ixz="-8.10719043328212E-08"
        iyy="2.55078709630884E-06"
        iyz="5.0234090402508E-08"
        izz="4.59669423156458E-07" />
    </inertial>
    <visual>
      <origin
        xyz="0 0 0"
        rpy="0 0 0" />
      <geometry>
        <mesh
          filename="package://myhexapod_description/meshes/link3_l5.STL" />
      </geometry>
      <material
        name="">
        <color
          rgba="1 0.0313725490196078 0.0627450980392157 1" />
      </material>
    </visual>
    <collision>
      <origin
        xyz="0 0 0"
        rpy="0 0 0" />
      <geometry>
        <mesh
          filename="package://myhexapod_description/meshes/link3_l5.STL" />
      </geometry>
    </collision>
  </link>
  <joint
    name="joint3_l5"
    type="continuous">
    <origin
      xyz="0.0412282335462067 -0.00331938514185891 0.00286714754488507"
      rpy="0 0 0" />
    <parent
      link="link2_l5" />
    <child
      link="link3_l5" />
    <axis
      xyz="-0.080252737926137 -0.996774547254974 0" />
  </joint>
  <link
    name="link1_l6">
    <inertial>
      <origin
        xyz="0.00867229299158234 -0.156799923922029 -0.0222013878562004"
        rpy="0 0 0" />
      <mass
        value="0.0173848381350191" />
      <inertia
        ixx="1.79837199620133E-06"
        ixy="5.22691790839105E-08"
        ixz="-1.84973613003036E-08"
        iyy="1.03731250985212E-06"
        iyz="7.3336665230342E-09"
        izz="1.46962126426456E-06" />
    </inertial>
    <visual>
      <origin
        xyz="0 0 0"
        rpy="0 0 0" />
      <geometry>
        <mesh
          filename="package://myhexapod_description/meshes/link1_l6.STL" />
      </geometry>
      <material
        name="">
        <color
          rgba="0.792156862745098 0.819607843137255 0.933333333333333 1" />
      </material>
    </visual>
    <collision>
      <origin
        xyz="0 0 0"
        rpy="0 0 0" />
      <geometry>
        <mesh
          filename="package://myhexapod_description/meshes/link1_l6.STL" />
      </geometry>
    </collision>
  </link>
  <joint
    name="joint1_l6"
    type="continuous">
    <origin
      xyz="0.0471936701061024 0.0668638986922139 0.0333"
      rpy="0 0 0" />
    <parent
      link="base_link" />
    <child
      link="link1_l6" />
    <axis
      xyz="0 0 -1" />
  </joint>
  <link
    name="link2_l6">
    <inertial>
      <origin
        xyz="0.0227094427868997 -0.160321179834648 -0.000453761122462593"
        rpy="0 0 0" />
      <mass
        value="0.0024160275032423" />
      <inertia
        ixx="7.8383638512418E-08"
        ixy="-4.22506491437897E-08"
        ixz="-5.37473177655586E-08"
        iyy="6.938433818688E-07"
        iyz="-3.67246918255262E-09"
        izz="6.24857624623141E-07" />
    </inertial>
    <visual>
      <origin
        xyz="0 0 0"
        rpy="0 0 0" />
      <geometry>
        <mesh
          filename="package://myhexapod_description/meshes/link2_l6.STL" />
      </geometry>
      <material
        name="">
        <color
          rgba="1 1 1 0.9" />
      </material>
    </visual>
    <collision>
      <origin
        xyz="0 0 0"
        rpy="0 0 0" />
      <geometry>
        <mesh
          filename="package://myhexapod_description/meshes/link2_l6.STL" />
      </geometry>
    </collision>
  </link>
  <joint
    name="joint2_l6"
    type="continuous">
    <origin
      xyz="0.0174901594158788 -0.0093354403553265 -0.0243000000000001"
      rpy="0 0 0" />
    <parent
      link="link1_l6" />
    <child
      link="link2_l6" />
    <axis
      xyz="0.0681694692047429 -0.997673756028665 0" />
  </joint>
  <link
    name="link3_l6">
    <inertial>
      <origin
        xyz="0.00348181655193414 -0.0140497997515956 0.00254707085294859"
        rpy="0 0 0" />
      <mass
        value="0.00980520879192993" />
      <inertia
        ixx="2.68084043695004E-06"
        ixy="8.60601987692669E-09"
        ixz="-5.30141833379143E-08"
        iyy="2.55057511653429E-06"
        iyz="4.00451291349846E-08"
        izz="4.57562057612305E-07" />
    </inertial>
    <visual>
      <origin
        xyz="0 0 0"
        rpy="0 0 0" />
      <geometry>
        <mesh
          filename="package://myhexapod_description/meshes/link3_l6.STL" />
      </geometry>
      <material
        name="">
        <color
          rgba="1 0.0313725490196078 0.0627450980392157 1" />
      </material>
    </visual>
    <collision>
      <origin
        xyz="0 0 0"
        rpy="0 0 0" />
      <geometry>
        <mesh
          filename="package://myhexapod_description/meshes/link3_l6.STL" />
      </geometry>
    </collision>
  </link>
  <joint
    name="joint3_l6"
    type="continuous">
    <origin
      xyz="0.0403470319862391 -0.130807993806323 -0.00896271435404228"
      rpy="0 0 0" />
    <parent
      link="link2_l6" />
    <child
      link="link3_l6" />
    <axis
      xyz="0.0681694692047429 -0.997673756028665 0" />
  </joint>
</robot>